# 9주차 과제
목표
- 자바의 예외 처리에 대해 학습하세요.

학습할것 필수
- 자바에서 예외 처리 방법 (try, catch, throw, throws, finally)
- 자바가 제공하는 예외 계층 구조
- Exception과 Error의 차이는?
- RuntimeException과 RE가 아닌 것의 차이는?
- 커스텀한 예외 만드는 방법

## 자바에서 예외 처리 방법 (try, catch, throw, throws, finally)
예외처리란?
- 프로그램 실행시 발생 할 수 있는 예외의 발생에 대비한 코드를 작성하는것
- 프로그램의 비정상 종료를 막고, 정상적인 실행 상태를 유지하는것

try-catch
- 예외를 처리하기 위해서 try-catch문 사용. 구조는 다음과 같음
~~~java
try {
    // 예외가 발생할 가능성이 있는 문장들을 넣는다.
} catch (Exception1 e1){
    // Exception1 이 발생했을 경우, 이를 처리하기 위한 문장을 적는다.
} catch (Exception2 e2){
  // Exception2가 발생했을 경우, 이를 처리하기 위한 문장을 적는다.
}
...
} catch (ExceptionN eN){
  // ExceptionN이 발생했을 경우, 이를 처리하기 위한 문장을 적는다.
}
~~~

try블럭 내에서 예외가 발생한 경우
1. 발생한 예외와 일치하는 catch블럭이 있는지 확인한다.
2. 일치하는 catch 블럭을 찾게되면, 그 catch블럭 내의 문장들을 수행하고 전체 try-catch문을 빠져나가서 그다음 문장을 계속해서 수행한다. 만일 일치하는 catch 블럭을 찾지 못하면 , 예외는 처리되지 못한다

~~~java
public class ExceptionEx {

    public static void main(String[] args) {
        System.out.println(1);
        System.out.println(2);

        try {
            System.out.println(3);
            System.out.println(0/0); // 고의로 ArithmeticException 발생
            System.out.println(4);
        } catch (Exception e) {
            System.out.println(5);
            e.printStackTrace();
        }// try-catch 끝

        System.out.println(6);
        // main 메소드 끝
    }
}

~~~
- 실행결과
~~~
1
2
3
5
6
~~~


try블럭 내에서 예외가 발생하지 않은 경우,
1. catch 블럭을 거치지 않고 전체 try-catch문을 빠져나가서 수행을 계속한다.
~~~java
public class ExceptionEx {

    public static void main(String[] args) {
        System.out.println(1);
        System.out.println(2);

        try {
            System.out.println(3);
            System.out.println(4);
        } catch (Exception e) {
            System.out.println(5);
            e.printStackTrace();
        }// try-catch 끝

        System.out.println(6);
        // main 메소드 끝 
    }
}
~~~
- 실행결과
~~~
1
2
3
4
6
~~~

throw
- 키워드 thow 를 사용하여 프로그래머가 고의로 예외를 발생 시킬수 있다
~~~java
public class ExceptionEx1 {
    public static void main(String[] args) {

        try {
            throw new Exception("고의로 Exception 발생");
        } catch (Exception e) {
            System.out.println("에러 메세지: " + e.getMessage());
            e.printStackTrace();
        }
        System.out.println("프로그램이 정상 종료되었음");
    }
}
~~~

throws
- 메서드에 예외를 선언하려면 메서드 선언부에 키워드 throws를 사용해서 메서드내에서 발생 할 수있는 예외를 적어주기만 하면된다. 예외가 여러개일 경우에는 쉼표(,) 로 구분한다.
- 예외를 메서드 throws 에 명시하는것은 예외처리가 아니라 자신을 호출한 메서드에게 예외를 전달하여 예외처리를 떠맡기는것
- 예외를 전달받은 메서드가 또 다시 자신을 호출한 메서드에게 전달 할 수 잇으며 이런식으로 계속 호출스택에 있는 메서들을 따라 전달되다가 제일마지막에 있는 main 메서드에서도 예외처리가 되지 않으면 main 메서드 마저 종료되어 프로그램이 전체가 종료된다.
~~~java
public class ExceptionEx2 {
    public static void main(String[] args) throws Exception {
        method1();
        // main 메서드의 끝
    }

    private static void method1() throws Exception {
        method2();
        // method1의 끝
    }

    private static void method2() throws Exception {
        throw new Exception();
        // method2의 끝
    }
}
~~~

finally 블럭
finally 블럭은 try-catch 문과 함께 예외의 발생여부에 상관엇ㅂ이 실행되어야 할 코드를 포함시킬 목적으로 사용된다. try-catch문의 끝에 선택적으로 덧붙여서 사용 할 수 있으며 try-catch-finally 순서로 구성된다.

- 예외가 발생한 경우에는 try -> catch -> finally의 순으로 실행되고, 예외가 발생하지 않은 경우에는 try -> finally 순으로 실행된다.
~~~java
public class ExceptionEx1 {
    public static void main(String[] args) {

        try {
            System.out.println("Inside try");
            throw new Exception();
        } catch (Exception e) {
            System.out.println("Inside catch");
        } finally {
            System.out.println("Inside finally");
        }
    }
}
~~~
- 실행 결과
~~~
Inside try
Inside catch
Inside finally
~~~

finally 블록 사용할 때 피해야되는 몇가지것들이 있음
그중에 하나는 예외를 무시하는 경우
- finally 블록의 return 문은 포착되지 않는 예외를 무시한다.
~~~java
public class ExceptionEx1 {
    public static void main(String[] args) {
        returnFinally();
    }

    public static String returnFinally() {
        try {
            System.out.println("Inside try");
            throw new RuntimeException();
        } finally {
            System.out.println("Inside finally");
            return "from finally";
        }
    }
}
~~~

- 실행결과는 아래와 같다.
~~~
Inside try
Inside finally
~~~
- **throw 로 RuntimeException 던졌지만 해당부분이 무시되고 finally가 실행된다.**
- finally 안에 리턴문을 사용할때는 주의가 필요하다!!


## 자바가 제공하는 예외 계층 구조
- 자바에서는 실행 시 발생할 수 있는 오류(Exception 과 Error)를 클래스로 정의하였다
- 모든 클래스의 조상은 Object 클래스이므로 Exception 과 Error 클래스 역시 Object 클래스 자손이다
- 모든 예외의 최고 조상은 Exception 클래스이다.
![KakaoTalk_Photo_2021-01-15-21-57-00](https://user-images.githubusercontent.com/38197944/104730136-d40b3e80-577c-11eb-8eb1-a892ef9b373f.jpeg)


## Exception과 Error의 차이는?
- 자바에서는 실행 시(runtime) 발생할 수 있는 프로그램 오류를 Error 와 Exception 두가지로 구분
- Error 는 메모리 부족(OutOfMemoryError)이나 , StackOverflowError 와 같이 일단 발생하면 복구 할 수 없는 심각한 오류
- Exception은 발생하면 프로그래머가 이에 대한 적절한 코드를 작성해 놓음으로써 프로그램의 비정상적인 종료를 막을 수 있다.
  
## RuntimeException과 RE가 아닌 것의 차이는?
- RuntimeException 은 Java Virtual Machine의 정상적인 작동중에 발생 할 수 있는 예외의 슈퍼 클래스이다.
- RuntimeException 및 해당 서브 클래스는 unchecked exception 이다
    - Unchecked exception 은 메서드 또는 생성자의 실행에 의해 발생한다
- 메소드 또는 생성자 경계외부로 전파 될 수 있는 경우 메소드 또는 새성자의 throws 절에서 선언될 필요가 없다.

Checked Exception 과 Unchecked(Runtime) Exception

|   | Checked Exception  |  Unchecked(Runtime) Exception |
|---|---|---|
| 처리여부| 반드시 예외를 처리해야함  | 명시적인 처리를 강제하지 않음  |
| 확인시점 | 컴파일 단계  | 실행단계 |
| 대표예외 | Exception 의 상속받는 하위 클래스 중 Runtime Exception을 제외한 모든 예외  <br> - IOException   <br>- SQL Exception   | Runtime Exception 하위 예외 <br> - NullPointerException <br>- IllegalArgumentExceptionn  |


## 커스텀한 예외 만드는 방법
- 기존에 정의된 예외 클래스 외에 필요에 따라 프로그래머가 새로운 예외 클래스를 정의하여 사용 할 수 있다
보통 Exception 클래스로부터 상속받는 클레스를 만들지만 필요에 따라 알맞은 예외 클래스를 선택 할 수 있다.
~~~java
class MyException extends Exception{
   MyException(Stirng msg) { // 문자열을 매개변수로 받는 생성자
      super(msg);
   }   
}
~~~
- Exception 클래스로부터 상속받아서 MyException 클래스를 만들었음. 필요하다면 멤버변수나 메서드를 추가할 수 있음
- Exception 클래스는 생성시에 String 값을 받아서 메세지로 저장 할 수 있다. 여러분이 만든 사용자 정의 예외 클래스도 메세지를 저장할 수 있으려면, 
위에서 보는것과 같이 String을 매개변수로 받는 생성자를 추가해줘야 한다.

~~~java
public class MyException extends Exception {
    // 에러코드 값을 저장하기 위한 필드를 추가
    private final int ERR_CODE; // 생성자를 통해 초기화 한다.

    public MyException(String msg, int errCode) {// 생성자
        super(msg);
        ERR_CODE = errCode;
    }

    public MyException(String message) {// 생성자
        this(message, 100);// ERR_CODE 를 100(기본값)으로 초기화
    }
    
    public int getErrCode(){
        return ERR_CODE;
    }
}
~~~
- 메세지 분만 아니라 에러코드 값도 저장 할 수 있도록 ERR_CODE 와 getErrCode()를 MyException 클래스 멤버로 추가한다
- 이렇게 함으로써 MyException 발생했을때 catch 블럭에서 getMessage() 와 GetErrCode 를 사용해서 에러코드와 메세지를 모두 얻을 수 있다.

- 아래와 같이 선언된 커스텀한 에러를 사용 할 수 있다.
~~~java
public class MyExceptionTest {

    public static void main(String[] args) {

        try {
            System.out.println("try catch");
            System.out.println("hi");
            throw new MyException("My Exception", 500);
        } catch (MyException e) {
            System.out.println("getMessage : "+e.getMessage()+"getErrCode : "+e.getErrCode());
        }
    }
}

~~~


## 참고
- 자바의 정석 책
- [Guide to the Java finally Keyword](https://www.baeldung.com/java-finally-keyword)
- [Checked Exception을 대하는 자세](https://cheese10yun.github.io/checked-exception/)
- [자바의 예외 - Exception, RuntimeException 그리고 Error](https://steady-hello.tistory.com/55)
[RuntimeException class](https://docs.oracle.com/javase/8/docs/api/java/lang/RuntimeException.html)